<mujoco model="RoboCrane">

    <!-- <compiler meshdir="assets" texturedir="asset"/> -->
    <compiler angle="radian" strippath="false" meshdir="/home/ubuntu/mujoco/assets" autolimits="true"/>
    <!-- <compiler angle="radian" strippath="false" meshdir="/home/geraldebmer/repos/robocrane/mujoco/assets" autolimits="true"/> -->
    <option impratio="10" integrator="implicit"/>
    <!-- <option gravity="0 0 10"/> -->
    <statistic extent="1.5" meansize=".05"/>

    <option timestep="0.001" jacobian="sparse" gravity="0 0 -9.81 "/>

    <keyframe>
        <key time="0" qpos="0 0 0 -1.5701 0 1.5701 0  0. 0. " />
    </keyframe>

  <actuator>
      <motor ctrllimited="true" ctrlrange="-320.0 320.0" joint="iiwa_joint_1" name="torq_j1"/>
      <motor ctrllimited="true" ctrlrange="-320.0 320.0" joint="iiwa_joint_2" name="torq_j2"/>
      <motor ctrllimited="true" ctrlrange="-176.0 176.0" joint="iiwa_joint_3" name="torq_j3"/>
      <motor ctrllimited="true" ctrlrange="-176.0 176.0" joint="iiwa_joint_4" name="torq_j4"/>
      <motor ctrllimited="true" ctrlrange="-110.0 110.0" joint="iiwa_joint_5" name="torq_j5"/>
      <motor ctrllimited="true" ctrlrange="-40.0 40.0" joint="iiwa_joint_6" name="torq_j6"/>
      <motor ctrllimited="true" ctrlrange="-40.0 40.0" joint="iiwa_joint_7" name="torq_j7"/>
  </actuator>


    <asset>
        <mesh name="link_0" file="meshes/base_link.stl" />
        <mesh name="link_1" file="meshes/link_1.stl" />
        <mesh name="link_2" file="meshes/link_2.stl" />
        <mesh name="link_3" file="meshes/link_3.stl" />
        <mesh name="link_4" file="meshes/link_4.stl" />
        <mesh name="link_5" file="meshes/link_5.stl" />
        <mesh name="link_6" file="meshes/link_6.stl" />
        <mesh name="link_7" file="meshes/link_7.stl" />

        <mesh name="cj_cam_mount" file="robocrane/cj_cam_mount_V2.obj" />
        <mesh name="cj_middle" file="robocrane/cj_middle.obj" />
        <mesh name="cj_bot" file="robocrane/cj_asm_half.obj" />

        <mesh name="cj_cam_mount_vis" file="robocrane/cj_cam_mount_V2_vis.obj" />
        <mesh name="cj_middle_vis" file="robocrane/cj_middle_vis.obj" />
        <mesh name="cj_bot_vis" file="robocrane/cj_asm_half_vis.obj" />

        <material name="metal" rgba="0.58 0.58 0.58 1"/>
        <material name="silicone" rgba="0.1882 0.1882 0.1882 1"/>
        <material name="gray" rgba="0.4627 0.4627 0.4627 1"/>
        <material name="black" rgba="0.149 0.149 0.149 1"/>
        <material name="wood" rgba="0.56 0.37 0.29 1"/>

        <mesh class="2f85" file="base_mount.stl"/>
        <mesh class="2f85" file="base.stl"/>
    
         <texture type="skybox" builtin="gradient" rgb1="0.3 0.5 0.7" rgb2="0 0 0" width="512" height="512"/>

        <texture name="texplane" type="2d" builtin="checker" rgb1=".2 .3 .4" rgb2=".1 0.15 0.2"
      width="512" height="512" mark="cross" markrgb=".8 .8 .8"/>
      <material name="matplane" reflectance="0.3" texture="texplane" texrepeat="1 1" texuniform="true"/>
    </asset>


<default>
    <default class="2f85">
      <mesh scale="0.001 0.001 0.001"/>
      <general biastype="affine"/>
      <joint axis="1 0 0"/>


      <default class="visual">
        <geom type="mesh" contype="0" conaffinity="0" group="2"/>
      </default>
      
      <default class="collision">
        <geom type="mesh" group="3"/>
      </default>
    </default> 
  </default>


    <worldbody>

      <light directional="true" diffuse=".4 .4 .4" specular="0.1 0.1 0.1" pos="0 0 5.0" dir="0 0 -1" castshadow="false"/>
      <light directional="true" diffuse=".6 .6 .6" specular="0.2 0.2 0.2" pos="0 0 4" dir="0 0 -1"/>

      <geom name="ground" type="plane" size="0 0 1" pos="0 0 0" quat="1 0 0 0" material="matplane" condim="1"/>

      <body name="iiwa_base" pos="0 0 0">
        <!-- robot view -->
        <camera mode="fixed" name="robotview" pos="1.0 0 0.4" quat="0.653 0.271 0.271 0.653"/>
        <inertial diaginertia="0 0 0" mass="0" pos="0 0 0"/>
        <!-- mount attached here -->
                  
        <geom type="mesh" contype="0" conaffinity="0" group="1" density="0" mesh="link_0" rgba="0.4 0.4 0.4 1"/>
        <geom type="mesh" mesh="link_0" rgba="0.4 0.4 0.4 1"/>

        <body name="iiwa_link_1" pos="0 0 0.1575">
          <inertial pos="0 -0.01439 0.102503" quat="1 0 0 0" mass="6.495" diaginertia="0.0690761441316632 0.0711085586914514 0.0200625854402119"/>
          <joint name="iiwa_joint_1" pos="0 0 0" axis="0 0 1" damping="0.0" limited="true" range="-2.96706 2.96706"/>
          <geom pos="0 0 -0.005" type="mesh" contype="0" conaffinity="0" group="1" density="0" mesh="link_1" rgba="0.4 0.4 0.4 1"/>
          <geom pos="0 0 -0.005" type="mesh" contype= "2" conaffinity="2" group="1" density="0" mesh="link_1" rgba="0.4 0.4 0.4 1"/>

          <body name="iiwa_link_2" pos="0 0 0.2025" quat="0 0 0.707107 0.707107">
            <inertial pos="1.2e-05 0.06472 0.004804" quat="1 0 0 0" mass="8.807" diaginertia="0.0824701683534692 0.0164110968055191 0.0873510892661361"/>
            <joint name="iiwa_joint_2" pos="0 0 0" axis="0 0 1" damping="0.0" limited="true" range="-2.0944 2.0944"/>
            <geom pos="0 0 -0.013" quat="0 0 0 1" type="mesh" contype="0" conaffinity="0" group="1" density="0" mesh="link_2" rgba="1 0.423529 0.0392157 1"/>
            <geom pos="0 0 -0.013" quat="0 0 0 1" type="mesh" mesh="link_2" rgba="1 0.423529 0.0392157 1"/>

            <body name="iiwa_link_3" pos="0 0.2375 0" quat="0 0 0.707107 0.707107">
              <inertial pos="-0.000208 0.01601 0.087283" quat="1 0 0 0" mass="2.8" diaginertia="0.0230152941318817 0.0228661554143474 0.0454482283748983"/>
              <joint name="iiwa_joint_3" pos="0 0 0" axis="0 0 1" damping="0.0" limited="true" range="-2.96706 2.96706"/>
              <geom pos="0 0 -0.005" type="mesh" contype="0" conaffinity="0" group="1" density="0" mesh="link_3" rgba="0.4 0.4 0.4 1"/>
              <geom pos="0 0 -0.005" type="mesh" contype="2" conaffinity="2" mesh="link_3" rgba="0.4 0.4 0.4 1"/>

              <body name="iiwa_link_4" pos="0 0 0.1825" quat="0.707107 0.707107 0 0">
                <inertial pos="-0.000203 0.098639 0.011478" quat="1 0 0 0" mass="5.283" diaginertia="0.0472789668341968 0.00964726804146909 0.0466529007761679"/>
                <joint name="iiwa_joint_4" pos="0 0 0" axis="0 0 1" damping="0.0" limited="true" range="-2.0944 2.0944"/>
                <geom pos="0 0 -0.011" type="mesh" contype="0" conaffinity="0" group="1" density="0" mesh="link_4" rgba="1 0.423529 0.0392157 1"/>
                <geom pos="0 0 -0.011" type="mesh" mesh="link_4" rgba="1 0.423529 0.0392157 1"/>

                <body name="iiwa_link_5" pos="0 0.2175 0" quat="0 0 0.707107 0.707107">
                  <inertial pos="5.7e-05 0.014468 0.062938" mass="1.889" diaginertia="0.0138359953358589 0.0116859337751969 0.00571863785412578"/>
                  <joint name="iiwa_joint_5" pos="0 0 0" axis="0 0 1" damping="0.0" limited="true" range="-2.96706 2.96706"/>
                  <geom pos="0 0 -0.005" quat="0 0 0 1" type="mesh" contype="0" conaffinity="0" group="1" density="0" mesh="link_5" rgba="0.4 0.4 0.4 1"/>
                  <geom pos="0 0 -0.005" quat="0 0 0 1" type="mesh" contype="2" conaffinity="2" mesh="link_5" rgba="0.4 0.4 0.4 1"/>

                  <body name="iiwa_link_6" pos="0 0 0.1825" quat="0.707107 0.707107 0 0">
                    <inertial pos="0.000363 0.016982 -0.019731" quat="1 0 0 0" mass="2.32" diaginertia="0.00732758787216765 0.00477633755783711 0.00606797638550296"/>
                    <joint name="iiwa_joint_6" pos="0 0 0" axis="0 0 1" damping="0.0" limited="true" range="-2.0944 2.0944"/>
                    <geom pos="0 0 -0.061" quat="0 0 0 1" type="mesh" contype="0" conaffinity="0" group="1" density="0" mesh="link_6" rgba="1 0.423529 0.0392157 1"/>
                    <geom pos="0 0 -0.061" quat="0 0 0 1" type="mesh" mesh="link_6" rgba="1 0.423529 0.0392157 1"/>

                    <body name="iiwa_link_7" pos="0 0.081 0" quat="0 0 0.707107 0.707107">
                      <inertial pos="0.001904 -9.3e-05 0.018862" quat="1 0 0 0" mass="0.863" diaginertia="0.000884 0.000888 0.001105"/>
                      <joint name="iiwa_joint_7" pos="0 0 0" axis="0 0 1" damping="0.0" limited="true" range="-3.05433 3.05433"/>
                      <geom pos="0 0 -0.001" type="mesh" contype="0" conaffinity="0" group="1" density="0" mesh="link_7" rgba="0.4 0.4 0.4 1"/>
                      <geom pos="0 0 -0.001" type="mesh" mesh="link_7" rgba="0.4 0.4 0.4 1"/>
                      
                      <!-- To add gripper -->
                      <body name="cj_top" pos="0 0 0.071" euler="0 0 0">
                        <inertial pos="0.0135 -0.0 0.02238" quat="1 0 0 0" mass="0.5" diaginertia="0.000124 0.000378 0.000425"/>                                          
                        <geom class="visual" contype="0" conaffinity="0" group="2" mesh="cj_cam_mount_vis" euler="0 0 1.5708"/>
                        <geom class="collision" contype="0" mesh="cj_cam_mount" euler="0 0 1.5708"/>
                        <!-- realsense camera -->
                        <camera mode="fixed" name="eye_in_hand" pos="0.075 0 0.02" euler="0 3.14159 1.5708" fovy="75"/>
                        
                        <body name="cj_middle" pos="0 0 0.07077" euler="0 0 0">
                          <inertial pos="0 0 0" quat="1 0 0 0" mass="0.016" diaginertia="0.000001 0.000001 0.000001"/>
                          <joint name="joint_cj1" pos="0 0 0" axis="1 0 0" limited="true" range="-0.785 0.785" damping="0.0" /> 
                          <geom class="visual" contype="0" conaffinity="0" group="2" mesh="cj_middle_vis" euler="1.5707963 0 0"/>
                          <geom class="collision" contype="0" conaffinity="0" mesh="cj_middle" euler="1.5707963 0 0"/>

                          <body name="cj_bot" pos="0 0 0.028" euler="0 0 0">
                            <inertial pos="0.0 0.0 0.05" quat="1 0 0 0" mass="1" diaginertia="0.0008 0.0008 0.001"/>
                            <joint name="joint_cj2" pos="0 0 -0.028" axis="0 1 0" limited="true" range="-0.785 0.785" damping="0.0" /> 
                            <geom class="visual" contype="0" conaffinity="0" group="2" mesh="cj_bot_vis" euler="3.1415926 0 1.5708"/>
                            <geom class="collision" contype="0" conaffinity="0" mesh="cj_bot" euler="3.1415926 0 1.5708"/>
                                          
                            <!-- robotiq 85 -->
                            <body name="base_mount" pos="0 0 0.0169" euler="0 0 0">
                              <geom class="visual" mesh="base_mount" material="black"/>
                              <geom class="collision" mesh="base_mount"/>
                              <inertial pos="0 -0. 0." quat="1 0 0 0" mass="1" diaginertia="0.0005 0.0005 0.0006"/>

                              <body name="base" pos="0 0 0.0038" quat="1 0 0 0">
                                <inertial mass="0.777441" pos="0 -2.70394e-05 0.0354675" quat="1 -0.00152849 0 0"
                                diaginertia="0.000260285 0.000225381 0.000152708"/>
                                <geom class="visual" mesh="base" material="black"/>
                                <geom class="collision" mesh="base"/>
                                <site name="pinch" pos="0 0 0.145" type="sphere" group="5" rgba="0.9 0.9 0.9 1" size="0.005"/>
                                

                              </body> 
                            </body>
                            <!-- robotiq 85 end -->

                          </body> <!-- cj_bot -->
                        </body> <!-- cj_middle -->
                      </body> <!-- cj_top -->

                    </body> <!-- link_7 -->
                  </body> <!-- link_6 -->
                </body> <!-- link_5 -->
              </body> <!-- link_4 -->
            </body> <!-- link_3 -->
          </body> <!-- link_2 -->
        </body> <!-- link_1 -->
      </body> <!-- iiwa_base -->



    </worldbody>

</mujoco>
